<?xml version="1.0"?>

<robot name="grabber">
  <link name="link1">
    <visual>
      <origin xyz="0 0 0.25" rpy="0 0 0" />
      <geometry> <box size=".5 .5 .5"/> </geometry>
      <material name="red"><color rgba="1 0 0 1" /> </material>
    </visual>
  </link>

  <link name="link2">
    <visual>
      <origin xyz="0 0 .5" rpy="0 0 0" />
      <geometry> <box size=".5 .5 1.0"/> </geometry>
      <material name="blue"><color rgba="0 0 1 1" /> </material>
    </visual>
  </link>

  <joint name="joint1" type="continuous">
    <parent link="link1"/>
    <child link="link2"/>
    <origin xyz="0 0 0.5" rpy="0 0 0" />
    <axis xyz="0 0 1" />
  </joint>

  <link name="link3">
    <visual>
      <origin xyz="0.75 0 0" rpy="0 0 0" />
      <geometry> <box size="1.5 .5 .5" /> </geometry>
      <material name="green"><color rgba="0 1 0 1" /> </material>
    </visual>
  </link>

  <joint name="joint2" type="continuous">
    <parent link="link2"/>
    <child link="link3"/>
    <origin xyz="0 0 1" rpy="0 0 0" />
    <axis xyz="0 -1 0" />
  </joint>

  <link name="link4">
    <visual>
      <origin xyz="0 -0.75 0" rpy="0 0 0" />
      <geometry> <box size="0.5 1.5 .5"/> </geometry>
      <material name="red"><color rgba="1 0 0 1" /> </material>
    </visual>
  </link>

  <joint name="joint3" type="continuous">
    <parent link="link3"/>
    <child link="link4"/>
    <origin xyz="1.5 0 0" rpy="0 0 0" />
    <axis xyz="0 0 1" />
  </joint>

  <link name="link5">
    <visual>
      <origin xyz="0 0 .5" rpy="0 0 0" />
      <geometry> <box size=".5 .5 1.0"/> </geometry>
      <material name="blue"><color rgba="0 0 1 1" /> </material>
    </visual>
  </link>

  <joint name="joint4" type="continuous">
    <parent link="link4"/>
    <child link="link5"/>
    <origin xyz="0 -1.5 0" rpy="1.57 0 0" />
    <axis xyz="0 0 1" />
  </joint>

  <link name="link6">
    <visual>
      <origin xyz="0.75 0 0" rpy="0 0 0" />
      <geometry> <box size="1.5 .5 .5" /> </geometry>
      <material name="green"><color rgba="0 1 0 1" /> </material>
    </visual>
  </link>

  <joint name="joint5" type="continuous">
    <parent link="link5"/>
    <child link="link6"/>
    <origin xyz="0 0 1" rpy="0 0 0" />
    <axis xyz="0 -1 0" />
  </joint>

  <link name="link7">
    <visual>
      <origin xyz="0 -0.75 0" rpy="0 0 0" />
      <geometry> <box size="0.5 1.5 .5"/> </geometry>
      <material name="red"><color rgba="1 0 0 1" /> </material>
    </visual>
  </link>

  <joint name="joint6" type="continuous">
    <parent link="link6"/>
    <child link="link7"/>
    <origin xyz="1.5 0 0" rpy="0 0 0" />
    <axis xyz="0 0 1" />
  </joint>

  <link name="link8">
    <visual>
      <origin xyz="0 -0.75 0" rpy="0 0 0" />
      <geometry> <box size="0.5 1.5 .5"/> </geometry>
      <material name="blue"><color rgba="0 0 1 1" /> </material>
    </visual>
  </link>

  <joint name="joint7" type="continuous">
    <parent link="link7"/>
    <child link="link8"/>
    <origin xyz="0 -1.5 0" rpy="0 0 0" />
    <axis xyz="0 1 0" />
  </joint>

  <link name="link9">
    <visual>
      <origin xyz="-0.5 -0.5 0" rpy="0 0 -0.75" />
      <geometry> <box size="0.5 1.5 .5"/> </geometry>
      <material name="red"><color rgba="1 0 0 1" /> </material>
    </visual>
  </link>

  <link name="link10">
    <visual>
      <origin xyz="0.5 -0.5 0" rpy="0 0 0.75" />
      <geometry> <box size="0.5 1.5 .5"/> </geometry>
      <material name="green"><color rgba="0 1 0 1" /> </material>
    </visual>
  </link>

  <joint name="joint8" type="continuous">
    <parent link="link8"/>
    <child link="link9"/>
    <origin xyz="0 -1.5 0" rpy="0 0 0" />
    <axis xyz="0 0 1" />
  </joint>

  <joint name="joint9" type="continuous">
    <parent link="link8"/>
    <child link="link10"/>
    <origin xyz="0 -1.5 0" rpy="0 0 0" />
    <axis xyz="0 0 1" />
  </joint>

  <link name="link11">
    <visual>
      <origin xyz="0 -0.5 0" rpy="0 0 0" />
      <geometry> <box size="0.5 1.5 .5"/> </geometry>
      <material name="blue"><color rgba="0 0 1 1" /> </material>
    </visual>
  </link>

  <joint name="joint10" type="continuous">
    <parent link="link9"/>
    <child link="link11"/>
    <origin xyz="-1.0 -1 0" rpy="0 0 0" />
    <axis xyz="0 0 1" />
  </joint>

  <link name="link12">
    <visual>
      <origin xyz="0 -0.5 0" rpy="0 0 0" />
      <geometry> <box size="0.5 1.5 .5"/> </geometry>
      <material name="red"><color rgba="1 0 0 1" /> </material>
    </visual>
  </link>

  <joint name="joint11" type="continuous">
    <parent link="link10"/>
    <child link="link12"/>
    <origin xyz="1.0 -1 0" rpy="0 0 0" />
    <axis xyz="0 0 1" />
  </joint>
</robot>
